<?php

declare(strict_types = 1);

namespace Rx\Functional\Promise;

use Exception;
use Rx\Functional\FunctionalTestCase;
use Rx\Observable;

class ToPromiseTest extends FunctionalTestCase
{
    /**
     * @test
     *
     */
    public function promise_success()
    {
        $promise = Observable::of(42)->toPromise();

        $result = null;

        $promise->then(function ($value) use (&$result) {
            $result = $value;
        });

        $this->assertEquals(42, $result);
    }

    /**
     * @test
     *
     */
    public function promise_failure()
    {
        $promise = Observable::error(new Exception('some error'))->toPromise();

        $error = null;

        $promise->then(
            function () {
            },
            function ($ex) use (&$error) {
                $error = $ex;
            });

        $this->assertEquals(new Exception('some error'), $error);
    }

    /**
     * @test
     *
     */
    public function promise_within_promise_success()
    {
        $promise1 = \React\Promise\resolve(42);

        $promise2 = Observable::of($promise1)->toPromise();

        $result = null;

        $promise2->then(function ($value) use (&$result) {
            $result = $value;
        });

        $this->assertEquals(42, $result);
    }

    /**
     * @test
     *
     */
    public function promise_within_promise_failure()
    {
        $promise1 = \React\Promise\reject(new Exception('some error'));

        $promise2 = Observable::of($promise1)->toPromise();

        $error = null;

        $promise2->then(
            function () {
            },
            function (Exception $ex) use (&$error) {
                $error = $ex;
            });

        $this->assertEquals(new Exception('some error'), $error);
    }
}
